<mujoco model="ur5e">
  <compiler autolimits="true"  meshdir="arm_assets"  angle="radian"/>
  
  <option impratio="10" integrator="implicitfast" cone="elliptic"/>
  
  <default>
    <default class="/">
      <default class="ur5e">
        <material specular="0.5" shininess="0.25"/>
        <joint axis="0 1 0" range="-6.28319 6.28319" armature="0.1"/>
        <site group="4" rgba="0.5 0.5 0.5 0.3" size="0.001"/>
        <general ctrlrange="-6.2831 6.2831" forcerange="-150 150" gaintype="fixed" biastype="affine" gainprm="2000" biasprm="0 -2000 -400"/>
        <default class="size3">
          <default class="size3_limited">
            <joint range="-3.1415 3.1415"/>
            <general ctrlrange="-3.1415 3.1415"/>
          </default>
        </default>
        <default class="size1">
          <general forcerange="-28 28" gainprm="500" biasprm="0 -500 -100"/>
        </default>
        <default class="visual">
          <geom type="mesh" contype="0" conaffinity="0" group="2"/>
        </default>
        <default class="collision">
          <geom type="capsule" group="3"/>
          <default class="eef_collision">
            <geom type="cylinder"/>
          </default>
        </default>
      </default>
    </default>
	
    <default class="robotiq_2f85/">
      <default class="robotiq_2f85/2f85">
        <mesh scale="0.001 0.001 0.001"/>
        <joint axis="1 0 0"/>
        <general biastype="affine"/>
        <default class="robotiq_2f85/driver">
          <joint solreflimit="0.005 1" solimplimit="0.95 0.99 0.001" range="0 0.8" armature="0.005" damping="0.1"/>
        </default>
        <default class="robotiq_2f85/follower">
          <joint pos="0 -0.018 0.0065" solreflimit="0.005 1" solimplimit="0.95 0.99 0.001" range="-0.872664 0.872664" armature="0.001"/>
        </default>
        <default class="robotiq_2f85/spring_link">
          <joint stiffness="0.05" range="-0.29670597283 0.8" springref="2.62" armature="0.001" damping="0.00125"/>
        </default>
        <default class="robotiq_2f85/coupler">
          <joint solreflimit="0.005 1" solimplimit="0.95 0.99 0.001" range="-1.57 0" armature="0.001"/>
        </default>
        <default class="robotiq_2f85/visual">
          <geom type="mesh" contype="0" conaffinity="0" group="2"/>
        </default>
        <default class="robotiq_2f85/collision">
          <geom type="mesh" group="3"/>
          <default class="robotiq_2f85/pad_box1">
            <geom type="box" priority="1" size="0.011 0.004 0.009375" rgba="0.55 0.55 0.55 1" friction="0.7" mass="0" solref="0.004 1" solimp="0.95 0.99 0.001" pos="0 -0.0026 0.028125"/>
          </default>
          <default class="robotiq_2f85/pad_box2">
            <geom type="box" priority="1" size="0.011 0.004 0.009375" rgba="0.45 0.45 0.45 1" friction="0.6" mass="0" solref="0.004 1" solimp="0.95 0.99 0.001" pos="0 -0.0026 0.009375"/>
          </default>
        </default>
      </default>
    </default>
  </default>
  
  <asset>
    <material name="black" class="ur5e" rgba="0.033 0.033 0.033 0.3"/>
    <material name="jointgray" class="ur5e" rgba="0.278 0.278 0.278 0.3"/>
    <material name="linkgray" class="ur5e" rgba="0.82 0.82 0.82 0.3"/>
    <material name="urblue" class="ur5e" rgba="0.49 0.678 0.8 0.3"/>
    <mesh name="base_0" class="/" file="base_0.obj"/>
    <mesh name="base_1" class="/" file="base_1.obj"/>
    <mesh name="shoulder_0" class="/" file="shoulder_0.obj"/>
    <mesh name="shoulder_1" class="/" file="shoulder_1.obj"/>
    <mesh name="shoulder_2" class="/" file="shoulder_2.obj"/>
    <mesh name="upperarm_0" class="/" file="upperarm_0.obj"/>
    <mesh name="upperarm_1" class="/" file="upperarm_1.obj"/>
    <mesh name="upperarm_2" class="/" file="upperarm_2.obj"/>
    <mesh name="upperarm_3" class="/" file="upperarm_3.obj"/>
    <mesh name="forearm_0" class="/" file="forearm_0.obj"/>
    <mesh name="forearm_1" class="/" file="forearm_1.obj"/>
    <mesh name="forearm_2" class="/" file="forearm_2.obj"/>
    <mesh name="forearm_3" class="/" file="forearm_3.obj"/>
    <mesh name="wrist1_0" class="/" file="wrist1_0.obj"/>
    <mesh name="wrist1_1" class="/" file="wrist1_1.obj"/>
    <mesh name="wrist1_2" class="/" file="wrist1_2.obj"/>
    <mesh name="wrist2_0" class="/" file="wrist2_0.obj"/>
    <mesh name="wrist2_1" class="/" file="wrist2_1.obj"/>
    <mesh name="wrist2_2" class="/" file="wrist2_2.obj"/>
    <mesh name="wrist3" class="/" file="wrist3.obj"/>
    <material name="robotiq_2f85/metal" class="robotiq_2f85/" rgba="0.58 0.58 0.58 1"/>
    <material name="robotiq_2f85/silicone" class="robotiq_2f85/" rgba="0.1882 0.1882 0.1882 1"/>
    <material name="robotiq_2f85/gray" class="robotiq_2f85/" rgba="0.4627 0.4627 0.4627 1"/>
    <material name="robotiq_2f85/black" class="robotiq_2f85/" rgba="0.149 0.149 0.149 1"/>
    <mesh name="robotiq_2f85/base_mount" class="robotiq_2f85/2f85" file="base_mount.stl"/>
    <mesh name="robotiq_2f85/base" class="robotiq_2f85/2f85" file="base.stl"/>
    <mesh name="robotiq_2f85/driver" class="robotiq_2f85/2f85" file="driver.stl"/>
    <mesh name="robotiq_2f85/coupler" class="robotiq_2f85/2f85" file="coupler.stl"/>
    <mesh name="robotiq_2f85/follower" class="robotiq_2f85/2f85" file="follower.stl"/>
    <mesh name="robotiq_2f85/pad" class="robotiq_2f85/2f85" file="pad.stl"/>
    <mesh name="robotiq_2f85/silicone_pad" class="robotiq_2f85/2f85" file="silicone_pad.stl"/>
    <mesh name="robotiq_2f85/spring_link" class="robotiq_2f85/2f85" file="spring_link.stl"/>
  </asset>
  
  
  <worldbody>
    <light name="spotlight" class="/" mode="targetbodycom" target="wrist_2_link" pos="0 -1 2"/>
    <body name="base" childclass="ur5e" quat="1 0 0 1">
      <inertial pos="0 0 0" mass="4" diaginertia="0.00443333156 0.00443333156 0.0072"/>
      <geom mesh="base_0" class="visual" material="black"/>
      <geom mesh="base_1" class="visual" material="jointgray"/>
      <body name="shoulder_link" pos="0 0 0.163">
        <inertial pos="0 0 0" mass="3.7" diaginertia="0.0102675 0.0102675 0.00666"/>
        <joint name="shoulder_pan_joint" class="size3" axis="0 0 1"/>
        <geom mesh="shoulder_0" material="urblue" class="visual"/>
        <geom mesh="shoulder_1" material="black" class="visual"/>
        <geom mesh="shoulder_2" material="jointgray" class="visual"/>
        <geom class="collision" size="0.06 0.06" pos="0 0 -0.04"/>
        <body name="upper_arm_link" pos="0 0.138 0" quat="1 0 1 0">
          <inertial pos="0 0 0.2125" mass="8.393" diaginertia="0.133886 0.133886 0.0151074"/>
          <joint name="shoulder_lift_joint" class="size3"/>
          <geom mesh="upperarm_0" material="linkgray" class="visual"/>
          <geom mesh="upperarm_1" material="black" class="visual"/>
          <geom mesh="upperarm_2" material="jointgray" class="visual"/>
          <geom mesh="upperarm_3" material="urblue" class="visual"/>
          <geom class="collision" size="0.06 0.06" pos="0 -0.04 0" quat="1 1 0 0"/>
          <geom class="collision" size="0.050 0.2" pos="0 0 0.2"/>
          <body name="forearm_link" pos="0 -0.131 0.425">
            <inertial pos="0 0 0.196" mass="2.275" diaginertia="0.0311796 0.0311796 0.004095"/>
            <joint name="elbow_joint" class="size3_limited"/>
            <geom mesh="forearm_0" class="visual" material="urblue"/>
            <geom mesh="forearm_1" class="visual" material="linkgray"/>
            <geom mesh="forearm_2" class="visual" material="black"/>
            <geom mesh="forearm_3" class="visual" material="jointgray"/>
            <geom class="collision" size="0.055 0.06" pos="0 0.08 0" quat="1 1 0 0"/>
            <geom class="collision" size="0.038 0.19" pos="0 0 0.2"/>
            <body name="wrist_1_link" pos="0 0 0.392" quat="1 0 1 0">
              <inertial pos="0 0.127 0" mass="1.219" diaginertia="0.0025599 0.0025599 0.0021942"/>
              <joint name="wrist_1_joint" class="size1"/>
              <geom mesh="wrist1_0" class="visual" material="black"/>
              <geom mesh="wrist1_1" class="visual" material="urblue"/>
              <geom mesh="wrist1_2" class="visual" material="jointgray"/>
              <geom class="collision" size="0.04 0.07" pos="0 0.05 0" quat="1 1 0 0"/>
              <body name="wrist_2_link" pos="0 0.127 0">
                <inertial pos="0 0 0.1" mass="1.219" diaginertia="0.0025599 0.0025599 0.0021942"/>
                <joint name="wrist_2_joint" class="size1" axis="0 0 1"/>
                <geom mesh="wrist2_0" class="visual" material="black"/>
                <geom mesh="wrist2_1" class="visual" material="urblue"/>
                <geom mesh="wrist2_2" class="visual" material="jointgray"/>
                <geom class="collision" size="0.04 0.06" pos="0 0 0.04"/>
                <geom class="collision" size="0.04 0.04" pos="0 0.02 0.1" quat="1 1 0 0"/>
                <body name="wrist_3_link" pos="0 0 0.1">
                  <inertial pos="0 0.0771683 0" quat="1 0 0 1" mass="0.1889" diaginertia="0.000132134 9.90863e-05 9.90863e-05"/>
                  <joint name="wrist_3_joint" class="size1"/>
                  <geom mesh="wrist3" class="visual" material="linkgray"/>
                  <geom class="eef_collision" size="0.04 0.02" pos="0 0.08 0" quat="1 1 0 0"/>
                  <site name="attachment_site" pos="0 0.1 0" quat="-1 1 0 0"/>
                  <body pos="0 0.1 0" quat="-1 1 0 0" name="robotiq_2f85/">
                    <body name="robotiq_2f85/base_mount" childclass="robotiq_2f85/2f85" pos="0 0 0.007">
                      <geom mesh="robotiq_2f85/base_mount" class="robotiq_2f85/visual" material="robotiq_2f85/black"/>
                      <geom mesh="robotiq_2f85/base_mount" class="robotiq_2f85/collision"/>
                      <body name="robotiq_2f85/base" pos="0 0 0.0038" quat="1 0 0 -1">
                        <inertial pos="0 -2.70394e-05 0.0354675" quat="1 -0.00152849 0 0" mass="0.777441" diaginertia="0.000260285 0.000225381 0.000152708"/>
                        <geom mesh="robotiq_2f85/base" class="robotiq_2f85/visual" material="robotiq_2f85/black"/>
                        <geom mesh="robotiq_2f85/base" class="robotiq_2f85/collision"/>
                        <site name="robotiq_2f85/pinch" type="sphere" group="5" rgba="0.9 0.9 0.9 1" size="0.005" pos="0 0 0.145"/>
						
						<camera name="camera_on_ee" mode="track" pos="-0.3 0 0.5" xyaxes="0 1 0 -1 0 -1"/>

						<body name="end_effector" pos="0 0 0.14"/>
						
                        <body name="robotiq_2f85/right_driver" pos="0 0.0306011 0.054904">
                          <inertial pos="2.96931e-12 0.0177547 0.00107314" quat="0.681301 0.732003 0 0" mass="0.00899563" diaginertia="1.72352e-06 1.60906e-06 3.22006e-07"/>
                          <joint name="robotiq_2f85/right_driver_joint" class="robotiq_2f85/driver"/>
                          <geom mesh="robotiq_2f85/driver" class="robotiq_2f85/visual" material="robotiq_2f85/gray"/>
                          <geom mesh="robotiq_2f85/driver" class="robotiq_2f85/collision"/>
                          <body name="robotiq_2f85/right_coupler" pos="0 0.0315 -0.0041">
                            <inertial pos="0 0.00301209 0.0232175" quat="0.705636 -0.0455904 0.0455904 0.705636" mass="0.0140974" diaginertia="4.16206e-06 3.52216e-06 8.88131e-07"/>
                            <joint name="robotiq_2f85/right_coupler_joint" class="robotiq_2f85/coupler"/>
                            <geom mesh="robotiq_2f85/coupler" class="robotiq_2f85/visual" material="robotiq_2f85/black"/>
                            <geom mesh="robotiq_2f85/coupler" class="robotiq_2f85/collision"/>
                          </body>
                        </body>
						
                        <body name="robotiq_2f85/right_spring_link" pos="0 0.0132 0.0609">
                          <inertial pos="-8.6500500000000008e-09 0.0181624 0.0212658" quat="0.663403 -0.244737 0.244737 0.663403" mass="0.0221642" diaginertia="8.96853e-06 6.71733e-06 2.63931e-06"/>
                          <joint name="robotiq_2f85/right_spring_link_joint" class="robotiq_2f85/spring_link"/>
                          <geom mesh="robotiq_2f85/spring_link" class="robotiq_2f85/visual" material="robotiq_2f85/black"/>
                          <geom mesh="robotiq_2f85/spring_link" class="robotiq_2f85/collision"/>
                          <body name="robotiq_2f85/right_follower" pos="0 0.055 0.0375">
                            <inertial pos="0 -0.011046 0.0124786" quat="1 0.1664 0 0" mass="0.0125222" diaginertia="2.67415e-06 2.4559e-06 6.02031e-07"/>
                            <joint name="robotiq_2f85/right_follower_joint" class="robotiq_2f85/follower"/>
                            <geom mesh="robotiq_2f85/follower" class="robotiq_2f85/visual" material="robotiq_2f85/black"/>
                            <geom mesh="robotiq_2f85/follower" class="robotiq_2f85/collision"/>
                            <body name="robotiq_2f85/right_pad" pos="0 -0.0189 0.01352">
                              <geom name="robotiq_2f85/right_pad1" class="robotiq_2f85/pad_box1"/>
                              <geom name="robotiq_2f85/right_pad2" class="robotiq_2f85/pad_box2"/>
                              <inertial pos="0 -0.0025 0.0185" quat="0.707107 0 0 0.707107" mass="0.0035" diaginertia="4.73958e-07 3.64583e-07 1.23958e-07"/>
                              <geom mesh="robotiq_2f85/pad" class="robotiq_2f85/visual"/>
                              <body name="robotiq_2f85/right_silicone_pad">
                                <geom mesh="robotiq_2f85/silicone_pad" class="robotiq_2f85/visual" material="robotiq_2f85/black"/>
                              </body>
                            </body>
                          </body>
                        </body>
						
                        <body name="robotiq_2f85/left_driver" pos="0 -0.0306011 0.054904" quat="0 0 0 1">
                          <inertial pos="0 0.0177547 0.00107314" quat="0.681301 0.732003 0 0" mass="0.00899563" diaginertia="1.72352e-06 1.60906e-06 3.22006e-07"/>
                          <joint name="robotiq_2f85/left_driver_joint" class="robotiq_2f85/driver"/>
                          <geom mesh="robotiq_2f85/driver" class="robotiq_2f85/visual" material="robotiq_2f85/gray"/>
                          <geom mesh="robotiq_2f85/driver" class="robotiq_2f85/collision"/>
                          <body name="robotiq_2f85/left_coupler" pos="0 0.0315 -0.0041">
                            <inertial pos="0 0.00301209 0.0232175" quat="0.705636 -0.0455904 0.0455904 0.705636" mass="0.0140974" diaginertia="4.16206e-06 3.52216e-06 8.8813100000000003e-07"/>
                            <joint name="robotiq_2f85/left_coupler_joint" class="robotiq_2f85/coupler"/>
                            <geom mesh="robotiq_2f85/coupler" class="robotiq_2f85/visual" material="robotiq_2f85/black"/>
                            <geom mesh="robotiq_2f85/coupler" class="robotiq_2f85/collision"/>
                          </body>
                        </body>
						
                        <body name="robotiq_2f85/left_spring_link" pos="0 -0.0132 0.0609" quat="0 0 0 1">
                          <inertial pos="-8.65005e-09 0.0181624 0.0212658" quat="0.663403 -0.244737 0.244737 0.663403" mass="0.0221642" diaginertia="8.96853e-06 6.71733e-06 2.63931e-06"/>
                          <joint name="robotiq_2f85/left_spring_link_joint" class="robotiq_2f85/spring_link"/>
                          <geom mesh="robotiq_2f85/spring_link" class="robotiq_2f85/visual" material="robotiq_2f85/black"/>
                          <geom mesh="robotiq_2f85/spring_link" class="robotiq_2f85/collision"/>
                          <body name="robotiq_2f85/left_follower" pos="0 0.055 0.0375">
                            <inertial pos="0 -0.011046 0.0124786" quat="1 0.1664 0 0" mass="0.0125222" diaginertia="2.67415e-06 2.4559e-06 6.02031e-07"/>
                            <joint name="robotiq_2f85/left_follower_joint" class="robotiq_2f85/follower"/>
                            <geom mesh="robotiq_2f85/follower" class="robotiq_2f85/visual" material="robotiq_2f85/black"/>
                            <geom mesh="robotiq_2f85/follower" class="robotiq_2f85/collision"/>
                            <body name="robotiq_2f85/left_pad" pos="0 -0.0189 0.01352">
                              <geom name="robotiq_2f85/left_pad1" class="robotiq_2f85/pad_box1"/>
                              <geom name="robotiq_2f85/left_pad2" class="robotiq_2f85/pad_box2"/>
                              <inertial pos="0 -0.0025 0.0185" quat="1 0 0 1" mass="0.0035" diaginertia="4.73958e-07 3.64583e-07 1.23958e-07"/>
                              <geom mesh="robotiq_2f85/pad" class="robotiq_2f85/visual"/>
                              <body name="robotiq_2f85/left_silicone_pad">
                                <geom mesh="robotiq_2f85/silicone_pad" class="robotiq_2f85/visual" material="robotiq_2f85/black"/>
                              </body>
                            </body>
                          </body>
                        </body>
                      </body>
                    </body>
                  </body>
                </body>
              </body>
            </body>
          </body>
        </body>
      </body>
    </body>
  </worldbody>
  
  
  <contact>
    <exclude body1="robotiq_2f85/base" body2="robotiq_2f85/left_driver"/>
    <exclude body1="robotiq_2f85/base" body2="robotiq_2f85/right_driver"/>
    <exclude body1="robotiq_2f85/base" body2="robotiq_2f85/left_spring_link"/>
    <exclude body1="robotiq_2f85/base" body2="robotiq_2f85/right_spring_link"/>
    <exclude body1="robotiq_2f85/right_coupler" body2="robotiq_2f85/right_follower"/>
    <exclude body1="robotiq_2f85/left_coupler" body2="robotiq_2f85/left_follower"/>
  </contact>
  
  <equality>
    <connect class="robotiq_2f85/" solref="0.005 1" solimp="0.95 0.99 0.001" body1="robotiq_2f85/right_follower" body2="robotiq_2f85/right_coupler" anchor="0 0 0"/>
    <connect class="robotiq_2f85/" solref="0.005 1" solimp="0.95 0.99 0.001" body1="robotiq_2f85/left_follower" body2="robotiq_2f85/left_coupler" anchor="0 0 0"/>
    <joint class="robotiq_2f85/" solref="0.005 1" solimp="0.95 0.99 0.001" joint1="robotiq_2f85/right_driver_joint" joint2="robotiq_2f85/left_driver_joint" polycoef="0 1 0 0 0"/>
  </equality>
  
  <tendon>
    <fixed name="robotiq_2f85/split" class="robotiq_2f85/">
      <joint joint="robotiq_2f85/right_driver_joint" coef="0.5"/>
      <joint joint="robotiq_2f85/left_driver_joint" coef="0.5"/>
    </fixed>
  </tendon>
  
  <actuator>
    <velocity name="shoulder_pan" class="size3" joint="shoulder_pan_joint"/>
    <velocity name="shoulder_lift" class="size3" joint="shoulder_lift_joint"/>
    <velocity name="elbow" class="size3_limited" joint="elbow_joint"/>
    <velocity name="wrist_1" class="size1" joint="wrist_1_joint"/>
    <velocity name="wrist_2" class="size1" joint="wrist_2_joint"/>
    <velocity name="wrist_3" class="size1" joint="wrist_3_joint"/>
    <general name="robotiq_2f85/fingers_actuator" class="robotiq_2f85/2f85" ctrlrange="0 255" forcerange="-5 5" tendon="robotiq_2f85/split" gainprm="0.3137255 0 0" biasprm="0 -100 -10"/>
  </actuator>
  
  <keyframe>
    <key name="home" ctrl="-1.5708 -1.5708 1.5708 -1.5708 -1.5708 0 0"/>	
  </keyframe>
</mujoco>
